<?xml version="1.0" ?>
<robot name="er6-730-mi">
  <link name="base">
  </link>
  <joint name="base_fixed" type="fixed">
    <parent link="base"/>
    <child link="base_link"/>
    <origin rpy="0 0 0.0" xyz="0.0 0.0 0.0"/>
  </joint>
  <link name="base_link">
    <visual>
      <origin rpy="0 0 0" xyz="0.0 0.0 0.0"/>
      <geometry>
        <mesh filename="meshes/base_link.stl" />
      </geometry>
    </visual>
    <collision>
      <origin rpy="0 0 0" xyz="0.0 0.0 0.0"/>
      <geometry>
        <mesh filename="meshes/base_link.stl" />
      </geometry>
    </collision>
    <inertial>
      <mass value="4.0"/>
      <origin rpy="0 0 0" xyz="0.0 0.0 0.0"/>
      <inertia ixx="0.00443333156" ixy="0.0" ixz="0.0" iyy="0.00443333156" iyz="0.0" izz="0.0072"/>
    </inertial>
  </link>
  <joint name="Rev1" type="revolute">
    <parent link="base_link"/>
    <child link="second_link"/>
    <origin rpy="3.14159265359 0 0" xyz="0.0 0.0 0.203"/>
    <axis xyz="0 0 1"/>
    <limit effort="150.0" lower="-2.96705973 " upper="2.96705973 " velocity="3.15"/>
  </joint>
  <link name="second_link">
    <visual>
      <origin rpy="3.14159265359 0 0" xyz="0.0 0.0 0.203"/>
      <geometry>
        <mesh filename="meshes/ER6-730-2_1.stl" />
      </geometry>
    </visual>
    <collision>
      <origin rpy="3.14159265359 0 0" xyz="0.0 0.0 0.203"/>
      <geometry>
        <mesh filename="meshes/ER6-730-2_1.stl" />
      </geometry>
    </collision>
    <inertial>
      <mass value="3.7"/>
      <origin rpy="0 0 0" xyz="0.0 0.0 0.0"/>
      <inertia ixx="0.010267495893" ixy="0.0" ixz="0.0" iyy="0.010267495893" iyz="0.0" izz="0.00666"/>
    </inertial>
  </link>
  <joint name="Rev2" type="revolute">
    <parent link="second_link"/>
    <child link="third_link"/>
    <origin rpy="1.57079632679 0 0" xyz="0.055 0.0 -0.201"/>
    <axis xyz="0 0 1"/>
    <limit effort="150.0" lower="-1.3962634" upper="2.26892803" velocity="3.15"/>
  </joint>
  <link name="third_link">
    <visual>
      <origin rpy="1.57079632679 0 0" xyz="-0.055 0.404 0.0"/>
      <geometry>
        <mesh filename="meshes/ER6-730-3_1.stl" />
      </geometry>
    </visual>
    <collision>
      <origin rpy="1.57079632679 0 0" xyz="-0.055 0.404 0.0"/>
      <geometry>
        <mesh filename="meshes/ER6-730-3_1.stl" />
      </geometry>
    </collision>
    <inertial>
      <mass value="8.393"/>
      <origin rpy="0 0 0" xyz="0.0 0.0 0.2125"/>
      <inertia ixx="0.133885781862" ixy="0.0" ixz="0.0" iyy="0.133885781862" iyz="0.0" izz="0.0151074"/>
    </inertial>
  </link>
  <joint name="Rev3" type="revolute">
    <parent link="third_link"/>
    <child link="fourth_link"/>
    <origin rpy="0 0 -1.57079632679" xyz="0.0 -0.33 0.0"/>
    <axis xyz="0 0 1"/>
    <limit effort="150.0" lower="-3.31612558" upper="1.13446401" velocity="3.15"/>
  </joint>
  <link name="fourth_link">
    <visual>
      <origin rpy="1.57079632679 0 1.57079632679" xyz="-0.734 -0.055 0.0"/>
      <geometry>
        <mesh filename="meshes/ER6-730-4_1.stl" />
      </geometry>
    </visual>
    <collision>
      <origin rpy="1.57079632679 0 1.57079632679" xyz="-0.734 -0.055 0.0"/>
      <geometry>
        <mesh filename="meshes/ER6-730-4_1.stl" />
      </geometry>
    </collision>
    <inertial>
      <mass value="2.275"/>
      <origin rpy="0 0 0" xyz="0.0 0.0 0.196"/>
      <inertia ixx="0.0311796208615" ixy="0.0" ixz="0.0" iyy="0.0311796208615" iyz="0.0" izz="0.004095"/>
    </inertial>
  </link>
  <joint name="Rev4" type="revolute">
    <parent link="fourth_link"/>
    <child link="fifth_link"/>
    <origin rpy="1.57079632679 0 0" xyz="0.045 0.0 0.0"/>
    <axis xyz="0 0 1"/>
    <limit effort="150.0" lower="-2.96705973 " upper="2.96705973" velocity="3.15"/>
  </joint>
  <link name="fifth_link">
    <visual>
      <origin rpy="0 1.57079632679 0" xyz="-0.779 0.0 0.055"/>
      <geometry>
        <mesh filename="meshes/ER6-730-5_1.stl" />
      </geometry>
    </visual>
    <collision>
      <origin rpy="0 1.57079632679 0" xyz="-0.779 0.0 0.055"/>
      <geometry>
        <mesh filename="meshes/ER6-730-5_1.stl" />
      </geometry>
    </collision>
    <inertial>
      <mass value="1.219"/>
      <origin rpy="0 0 0" xyz="0.0 0.127 0.0"/>
      <inertia ixx="0.00255989897604" ixy="0.0" ixz="0.0" iyy="0.00255989897604" iyz="0.0" izz="0.0021942"/>
    </inertial>
  </link>
  <joint name="Rev5" type="revolute">
    <parent link="fifth_link"/>
    <child link="sixth_link"/>
    <origin rpy="-1.57079632679 0 0" xyz="0.0 0.0 -0.34"/>
    <axis xyz="0 0 1"/>
    <limit effort="150.0" lower="-2.26892803" upper="2.26892803" velocity="3.15"/>
  </joint>
  <link name="sixth_link">
    <visual>
      <origin rpy="1.57079632679 0 1.57079632679" xyz="-0.779 -0.395 0.0"/>
      <geometry>
        <mesh filename="meshes/ER6-730-05-1_1.stl" />
      </geometry>
    </visual>
    <collision>
      <origin rpy="1.57079632679 0 1.57079632679" xyz="-0.779 -0.395 0.0"/>
      <geometry>
        <mesh filename="meshes/ER6-730-05-1_1.stl" />
      </geometry>
    </collision>
    <inertial>
      <mass value="1.219"/>
      <origin rpy="0 0 0" xyz="0.0 0.0 0.1"/>
      <inertia ixx="0.00255989897604" ixy="0.0" ixz="0.0" iyy="0.00255989897604" iyz="0.0" izz="0.0021942"/>
    </inertial>
  </link>
  <joint name="Rev6" type="revolute">
    <parent link="sixth_link"/>
    <child link="seventh_link"/>
    <origin rpy="1.57079632679 0 0" xyz="0.0 0.0 0.0"/>
    <axis xyz="0 0 1"/>
    <limit effort="150.0" lower="-6.28318530718" upper="6.28318530718" velocity="3.15"/>
  </joint>
  <link name="seventh_link">
    <visual>
      <origin rpy="0.0 1.57079632679 0" xyz="-0.779 0.0 0.395"/>
      <geometry>
        <mesh filename="meshes/ER6-730-06_1.stl" />
      </geometry>
    </visual>
    <collision>
      <origin rpy="0.0 1.57079632679 0" xyz="-0.779 0.0 0.395"/>
      <geometry>
        <mesh filename="meshes/ER6-730-06_1.stl" />
      </geometry>
    </collision>
    <inertial>
      <mass value="0.1879"/>
      <origin rpy="1.57079632679 0 0" xyz="0.0 0.0771 0.0"/>
      <inertia ixx="9.89041005217e-05" ixy="0.0" ixz="0.0" iyy="9.89041005217e-05" iyz="0.0" izz="0.0001321171875"/>
    </inertial>
  </link>
  <joint name="ee_fixed_joint" type="fixed">
    <parent link="seventh_link"/>
    <child link="ee_link"/>
    <origin rpy="3.14159265359 0.0 0.0" xyz="0.00092 0.0 -0.08682"/>
  </joint>
  <link name="ee_link">
    <collision>
      <geometry>
        <box size="0.01 0.01 0.01"/>
      </geometry>
      <origin rpy="0 0 0" xyz="-0.01 0 0"/>
    </collision>
  </link>
</robot>
