<?xml version="1.0" ?>
<robot name="er6-730-mi">
  <link name="base">
  </link>
  <joint name="base_fixed" type="fixed">
    <parent link="base"/>
    <child link="base_link"/>
    <origin rpy="0 0 3.14" xyz="0.0 0.0 0.0"/>
  </joint>
  <link name="base_link">
    <visual>
      <origin rpy="0 0 0" xyz="0.0 0.0 0.0"/>
      <geometry>
        <mesh filename="meshes/base_link.stl" />
      </geometry>
    </visual>
    <collision>
      <origin rpy="0 0 0" xyz="0.0 0.0 0.0"/>
      <geometry>
        <mesh filename="meshes/base_link.stl" />
      </geometry>
    </collision>
  </link>
  <joint name="Rev1" type="revolute">
    <parent link="base_link"/>
    <child link="second_link"/>
    <origin rpy="3.14159265359 0 0" xyz="0.0 0.0 0.203"/>
    <axis xyz="0 0 1"/>
    <limit effort="150.0" lower="-2.96705973 " upper="2.96705973 " velocity="3.15"/>
  </joint>
  <link name="second_link">
    <visual>
      <origin rpy="3.14159265359 0 0" xyz="0.0 0.0 0.203"/>
      <geometry>
        <mesh filename="meshes/ER6-730-2_1.stl" />
      </geometry>
    </visual>
    <collision>
      <origin rpy="3.14159265359 0 0" xyz="0.0 0.0 0.203"/>
      <geometry>
        <mesh filename="meshes/ER6-730-2_1.stl" />
      </geometry>
    </collision>
  </link>
  <joint name="Rev2" type="revolute">
    <parent link="second_link"/>
    <child link="third_link"/>
    <origin rpy="1.57079632679 0 0" xyz="0.055 0.0 -0.201"/>
    <axis xyz="0 0 1"/>
    <limit effort="150.0" lower="-1.3962634" upper="2.26892803" velocity="3.15"/>
  </joint>
  <link name="third_link">
    <visual>
      <origin rpy="1.57079632679 0 0" xyz="-0.055 0.404 0.0"/>
      <geometry>
        <mesh filename="meshes/ER6-730-3_1.stl" />
      </geometry>
    </visual>
    <collision>
      <origin rpy="1.57079632679 0 0" xyz="-0.055 0.404 0.0"/>
      <geometry>
        <mesh filename="meshes/ER6-730-3_1.stl" />
      </geometry>
    </collision>
  </link>
  <joint name="Rev3" type="revolute">
    <parent link="third_link"/>
    <child link="fourth_link"/>
    <origin rpy="0 0 -1.57079632679" xyz="0.0 -0.33 0.0"/>
    <axis xyz="0 0 1"/>
    <limit effort="150.0" lower="-3.31612558" upper="1.13446401" velocity="3.15"/>
  </joint>
  <link name="fourth_link">
    <visual>
      <origin rpy="1.57079632679 0 1.57079632679" xyz="-0.734 -0.055 0.0"/>
      <geometry>
        <mesh filename="meshes/ER6-730-4_1.stl" />
      </geometry>
    </visual>
    <collision>
      <origin rpy="1.57079632679 0 1.57079632679" xyz="-0.734 -0.055 0.0"/>
      <geometry>
        <mesh filename="meshes/ER6-730-4_1.stl" />
      </geometry>
    </collision>
  </link>
  <joint name="Rev4" type="revolute">
    <parent link="fourth_link"/>
    <child link="fifth_link"/>
    <origin rpy="1.57079632679 0 0" xyz="0.045 0.0 0.0"/>
    <axis xyz="0 0 1"/>
    <limit effort="150.0" lower="-2.96705973 " upper="2.96705973" velocity="3.15"/>
  </joint>
  <link name="fifth_link">
    <visual>
      <origin rpy="0 1.57079632679 0" xyz="-0.779 0.0 0.055"/>
      <geometry>
        <mesh filename="meshes/ER6-730-5_1.stl" />
      </geometry>
    </visual>
    <collision>
      <origin rpy="0 1.57079632679 0" xyz="-0.779 0.0 0.055"/>
      <geometry>
        <mesh filename="meshes/ER6-730-5_1.stl" />
      </geometry>
    </collision>
  </link>
  <joint name="Rev5" type="revolute">
    <parent link="fifth_link"/>
    <child link="sixth_link"/>
    <origin rpy="-1.57079632679 0 0" xyz="0.0 0.0 -0.34"/>
    <axis xyz="0 0 1"/>
    <limit effort="150.0" lower="-2.26892803" upper="2.26892803" velocity="3.15"/>
  </joint>
  <link name="sixth_link">
    <visual>
      <origin rpy="1.57079632679 0 1.57079632679" xyz="-0.779 -0.395 0.0"/>
      <geometry>
        <mesh filename="meshes/ER6-730-05-1_1.stl" />
      </geometry>
    </visual>
    <collision>
      <origin rpy="1.57079632679 0 1.57079632679" xyz="-0.779 -0.395 0.0"/>
      <geometry>
        <mesh filename="meshes/ER6-730-05-1_1.stl" />
      </geometry>
    </collision>
  </link>
  <joint name="Rev6" type="revolute">
    <parent link="sixth_link"/>
    <child link="seventh_link"/>
    <origin rpy="1.57079632679 0 0" xyz="0.0 0.0 0.0"/>
    <axis xyz="0 0 1"/>
    <limit effort="150.0" lower="-6.28318530718" upper="6.28318530718" velocity="3.15"/>
  </joint>
  <link name="seventh_link">
    <visual>
      <origin rpy="0.0 1.57079632679 0" xyz="-0.779 0.0 0.395"/>
      <geometry>
        <mesh filename="meshes/ER6-730-06_1.stl" />
      </geometry>
    </visual>
    <collision>
      <origin rpy="0.0 1.57079632679 0" xyz="-0.779 0.0 0.395"/>
      <geometry>
        <mesh filename="meshes/ER6-730-06_1.stl" />
      </geometry>
    </collision>
  </link>
  <joint name="ee_fixed_joint" type="fixed">
    <parent link="seventh_link"/>
    <child link="ee_link"/>
    <origin rpy="3.14159265359 0.0 0.0" xyz="0.00092 0.0 -0.08682"/>
  </joint>
  <link name="ee_link">
  </link>
</robot>
